[2025-05-18T14:36:06.315+0000] {taskinstance.py:1956} INFO - Dependencies all met for dep_context=non-requeueable deps ti=<TaskInstance: nyc_taxi_pipeline.load_data manual__2025-05-18T14:26:20.985562+00:00 [queued]>
[2025-05-18T14:36:06.333+0000] {taskinstance.py:1956} INFO - Dependencies all met for dep_context=requeueable deps ti=<TaskInstance: nyc_taxi_pipeline.load_data manual__2025-05-18T14:26:20.985562+00:00 [queued]>
[2025-05-18T14:36:06.335+0000] {taskinstance.py:2170} INFO - Starting attempt 2 of 2
[2025-05-18T14:36:06.360+0000] {taskinstance.py:2191} INFO - Executing <Task(PythonOperator): load_data> on 2025-05-18 14:26:20.985562+00:00
[2025-05-18T14:36:06.367+0000] {standard_task_runner.py:60} INFO - Started process 184 to run task
[2025-05-18T14:36:06.372+0000] {standard_task_runner.py:87} INFO - Running: ['***', 'tasks', 'run', 'nyc_taxi_pipeline', 'load_data', 'manual__2025-05-18T14:26:20.985562+00:00', '--job-id', '10', '--raw', '--subdir', 'DAGS_FOLDER/nyc_taxi_pipeline.py', '--cfg-path', '/tmp/tmplhgmk4u5']
[2025-05-18T14:36:06.375+0000] {standard_task_runner.py:88} INFO - Job 10: Subtask load_data
[2025-05-18T14:36:06.398+0000] {logging_mixin.py:188} WARNING - /home/***/.local/lib/python3.8/site-packages/***/settings.py:194 DeprecationWarning: The sql_alchemy_conn option in [core] has been moved to the sql_alchemy_conn option in [database] - the old setting has been used, but please update your config.
[2025-05-18T14:36:06.450+0000] {task_command.py:423} INFO - Running <TaskInstance: nyc_taxi_pipeline.load_data manual__2025-05-18T14:26:20.985562+00:00 [running]> on host 0a1869ecb872
[2025-05-18T14:36:06.778+0000] {taskinstance.py:2480} INFO - Exporting env vars: AIRFLOW_CTX_DAG_OWNER='***' AIRFLOW_CTX_DAG_ID='nyc_taxi_pipeline' AIRFLOW_CTX_TASK_ID='load_data' AIRFLOW_CTX_EXECUTION_DATE='2025-05-18T14:26:20.985562+00:00' AIRFLOW_CTX_TRY_NUMBER='2' AIRFLOW_CTX_DAG_RUN_ID='manual__2025-05-18T14:26:20.985562+00:00'
[2025-05-18T14:36:06.780+0000] {nyc_taxi_pipeline.py:50} INFO - Starting data loading...
[2025-05-18T14:36:06.785+0000] {taskinstance.py:2698} ERROR - Task failed with exception
Traceback (most recent call last):
  File "/home/airflow/.local/lib/python3.8/site-packages/airflow/models/taskinstance.py", line 433, in _execute_task
    result = execute_callable(context=context, **execute_callable_kwargs)
  File "/home/airflow/.local/lib/python3.8/site-packages/airflow/operators/python.py", line 199, in execute
    return_value = self.execute_callable()
  File "/home/airflow/.local/lib/python3.8/site-packages/airflow/operators/python.py", line 216, in execute_callable
    return self.python_callable(*self.op_args, **self.op_kwargs)
  File "/opt/airflow/dags/nyc_taxi_pipeline.py", line 58, in load_callable
    df = pd.read_parquet(cleaned_path)
  File "/home/airflow/.local/lib/python3.8/site-packages/pandas/io/parquet.py", line 509, in read_parquet
    return impl.read(
  File "/home/airflow/.local/lib/python3.8/site-packages/pandas/io/parquet.py", line 220, in read
    path_or_handle, handles, kwargs["filesystem"] = _get_path_or_handle(
  File "/home/airflow/.local/lib/python3.8/site-packages/pandas/io/parquet.py", line 110, in _get_path_or_handle
    handles = get_handle(
  File "/home/airflow/.local/lib/python3.8/site-packages/pandas/io/common.py", line 868, in get_handle
    handle = open(handle, ioargs.mode)
FileNotFoundError: [Errno 2] No such file or directory: 'C:\\Users\\jorda\\OneDrive\\Documents\\nyc-taxi-pipeline-1\\Data\\Raw\\Processed\\cleaned_data.parquet'
[2025-05-18T14:36:06.805+0000] {taskinstance.py:1138} INFO - Marking task as FAILED. dag_id=nyc_taxi_pipeline, task_id=load_data, execution_date=20250518T142620, start_date=20250518T143606, end_date=20250518T143606
[2025-05-18T14:36:06.826+0000] {standard_task_runner.py:107} ERROR - Failed to execute job 10 for task load_data ([Errno 2] No such file or directory: 'C:\\Users\\jorda\\OneDrive\\Documents\\nyc-taxi-pipeline-1\\Data\\Raw\\Processed\\cleaned_data.parquet'; 184)
[2025-05-18T14:36:06.866+0000] {local_task_job_runner.py:234} INFO - Task exited with return code 1
[2025-05-18T14:36:06.893+0000] {taskinstance.py:3280} INFO - 0 downstream tasks scheduled from follow-on schedule check
