[2025-05-19T09:38:48.583+0000] {taskinstance.py:1956} INFO - Dependencies all met for dep_context=non-requeueable deps ti=<TaskInstance: nyc_taxi_pipeline.load_data manual__2025-05-19T09:37:46.419219+00:00 [queued]>
[2025-05-19T09:38:48.598+0000] {taskinstance.py:1956} INFO - Dependencies all met for dep_context=requeueable deps ti=<TaskInstance: nyc_taxi_pipeline.load_data manual__2025-05-19T09:37:46.419219+00:00 [queued]>
[2025-05-19T09:38:48.599+0000] {taskinstance.py:2170} INFO - Starting attempt 1 of 2
[2025-05-19T09:38:48.619+0000] {taskinstance.py:2191} INFO - Executing <Task(PythonOperator): load_data> on 2025-05-19 09:37:46.419219+00:00
[2025-05-19T09:38:48.626+0000] {standard_task_runner.py:60} INFO - Started process 215 to run task
[2025-05-19T09:38:48.630+0000] {standard_task_runner.py:87} INFO - Running: ['***', 'tasks', 'run', 'nyc_taxi_pipeline', 'load_data', 'manual__2025-05-19T09:37:46.419219+00:00', '--job-id', '44', '--raw', '--subdir', 'DAGS_FOLDER/nyc_taxi_pipeline.py', '--cfg-path', '/tmp/tmpel39c00l']
[2025-05-19T09:38:48.634+0000] {standard_task_runner.py:88} INFO - Job 44: Subtask load_data
[2025-05-19T09:38:48.656+0000] {logging_mixin.py:188} WARNING - /home/***/.local/lib/python3.8/site-packages/***/settings.py:194 DeprecationWarning: The sql_alchemy_conn option in [core] has been moved to the sql_alchemy_conn option in [database] - the old setting has been used, but please update your config.
[2025-05-19T09:38:48.701+0000] {task_command.py:423} INFO - Running <TaskInstance: nyc_taxi_pipeline.load_data manual__2025-05-19T09:37:46.419219+00:00 [running]> on host abdac7c06155
[2025-05-19T09:38:48.995+0000] {taskinstance.py:2480} INFO - Exporting env vars: AIRFLOW_CTX_DAG_OWNER='***' AIRFLOW_CTX_DAG_ID='nyc_taxi_pipeline' AIRFLOW_CTX_TASK_ID='load_data' AIRFLOW_CTX_EXECUTION_DATE='2025-05-19T09:37:46.419219+00:00' AIRFLOW_CTX_TRY_NUMBER='1' AIRFLOW_CTX_DAG_RUN_ID='manual__2025-05-19T09:37:46.419219+00:00'
[2025-05-19T09:38:48.997+0000] {nyc_taxi_pipeline.py:50} INFO - Starting data loading...
[2025-05-19T09:38:49.014+0000] {load.py:67} ERROR - Failed during chunked parquet upload: read_table() got an unexpected keyword argument 'chunksize'
Traceback (most recent call last):
  File "/opt/airflow/scripts/load.py", line 56, in upload_parquet_in_chunks
    df_iter = pd.read_parquet(parquet_file, chunksize=chunksize)
  File "/home/airflow/.local/lib/python3.8/site-packages/pandas/io/parquet.py", line 509, in read_parquet
    return impl.read(
  File "/home/airflow/.local/lib/python3.8/site-packages/pandas/io/parquet.py", line 227, in read
    pa_table = self.api.parquet.read_table(
TypeError: read_table() got an unexpected keyword argument 'chunksize'
[2025-05-19T09:38:49.021+0000] {nyc_taxi_pipeline.py:69} INFO - Data successfully loaded
[2025-05-19T09:38:49.022+0000] {python.py:201} INFO - Done. Returned value was: None
[2025-05-19T09:38:49.034+0000] {taskinstance.py:1138} INFO - Marking task as SUCCESS. dag_id=nyc_taxi_pipeline, task_id=load_data, execution_date=20250519T093746, start_date=20250519T093848, end_date=20250519T093849
[2025-05-19T09:38:49.085+0000] {local_task_job_runner.py:234} INFO - Task exited with return code 0
[2025-05-19T09:38:49.108+0000] {taskinstance.py:3280} INFO - 0 downstream tasks scheduled from follow-on schedule check
