[2025-05-18T14:27:38.233+0000] {taskinstance.py:1956} INFO - Dependencies all met for dep_context=non-requeueable deps ti=<TaskInstance: nyc_taxi_pipeline.load_data manual__2025-05-18T14:04:17.620684+00:00 [queued]>
[2025-05-18T14:27:38.255+0000] {taskinstance.py:1956} INFO - Dependencies all met for dep_context=requeueable deps ti=<TaskInstance: nyc_taxi_pipeline.load_data manual__2025-05-18T14:04:17.620684+00:00 [queued]>
[2025-05-18T14:27:38.256+0000] {taskinstance.py:2170} INFO - Starting attempt 1 of 2
[2025-05-18T14:27:38.279+0000] {taskinstance.py:2191} INFO - Executing <Task(PythonOperator): load_data> on 2025-05-18 14:04:17.620684+00:00
[2025-05-18T14:27:38.285+0000] {standard_task_runner.py:60} INFO - Started process 240 to run task
[2025-05-18T14:27:38.291+0000] {standard_task_runner.py:87} INFO - Running: ['***', 'tasks', 'run', 'nyc_taxi_pipeline', 'load_data', 'manual__2025-05-18T14:04:17.620684+00:00', '--job-id', '8', '--raw', '--subdir', 'DAGS_FOLDER/nyc_taxi_pipeline.py', '--cfg-path', '/tmp/tmpzq476a4t']
[2025-05-18T14:27:38.295+0000] {standard_task_runner.py:88} INFO - Job 8: Subtask load_data
[2025-05-18T14:27:38.319+0000] {logging_mixin.py:188} WARNING - /home/***/.local/lib/python3.8/site-packages/***/settings.py:194 DeprecationWarning: The sql_alchemy_conn option in [core] has been moved to the sql_alchemy_conn option in [database] - the old setting has been used, but please update your config.
[2025-05-18T14:27:38.374+0000] {task_command.py:423} INFO - Running <TaskInstance: nyc_taxi_pipeline.load_data manual__2025-05-18T14:04:17.620684+00:00 [running]> on host 94eccf45184c
[2025-05-18T14:27:38.681+0000] {taskinstance.py:2480} INFO - Exporting env vars: AIRFLOW_CTX_DAG_OWNER='***' AIRFLOW_CTX_DAG_ID='nyc_taxi_pipeline' AIRFLOW_CTX_TASK_ID='load_data' AIRFLOW_CTX_EXECUTION_DATE='2025-05-18T14:04:17.620684+00:00' AIRFLOW_CTX_TRY_NUMBER='1' AIRFLOW_CTX_DAG_RUN_ID='manual__2025-05-18T14:04:17.620684+00:00'
[2025-05-18T14:27:38.683+0000] {nyc_taxi_pipeline.py:50} INFO - Starting data loading...
[2025-05-18T14:27:38.686+0000] {taskinstance.py:2698} ERROR - Task failed with exception
Traceback (most recent call last):
  File "/home/airflow/.local/lib/python3.8/site-packages/airflow/models/taskinstance.py", line 433, in _execute_task
    result = execute_callable(context=context, **execute_callable_kwargs)
  File "/home/airflow/.local/lib/python3.8/site-packages/airflow/operators/python.py", line 199, in execute
    return_value = self.execute_callable()
  File "/home/airflow/.local/lib/python3.8/site-packages/airflow/operators/python.py", line 216, in execute_callable
    return self.python_callable(*self.op_args, **self.op_kwargs)
  File "/opt/airflow/dags/nyc_taxi_pipeline.py", line 57, in load_callable
    df = pd.read_parquet(cleaned_path)
  File "/home/airflow/.local/lib/python3.8/site-packages/pandas/io/parquet.py", line 509, in read_parquet
    return impl.read(
  File "/home/airflow/.local/lib/python3.8/site-packages/pandas/io/parquet.py", line 220, in read
    path_or_handle, handles, kwargs["filesystem"] = _get_path_or_handle(
  File "/home/airflow/.local/lib/python3.8/site-packages/pandas/io/parquet.py", line 110, in _get_path_or_handle
    handles = get_handle(
  File "/home/airflow/.local/lib/python3.8/site-packages/pandas/io/common.py", line 868, in get_handle
    handle = open(handle, ioargs.mode)
FileNotFoundError: [Errno 2] No such file or directory: 'C:\\Users\\jorda\\OneDrive\\Documents\\nyc-taxi-pipeline-1\\Data\\Raw\\Processed\\cleaned_data.parquet'
[2025-05-18T14:27:38.704+0000] {taskinstance.py:1138} INFO - Marking task as UP_FOR_RETRY. dag_id=nyc_taxi_pipeline, task_id=load_data, execution_date=20250518T140417, start_date=20250518T142738, end_date=20250518T142738
[2025-05-18T14:27:38.724+0000] {standard_task_runner.py:107} ERROR - Failed to execute job 8 for task load_data ([Errno 2] No such file or directory: 'C:\\Users\\jorda\\OneDrive\\Documents\\nyc-taxi-pipeline-1\\Data\\Raw\\Processed\\cleaned_data.parquet'; 240)
[2025-05-18T14:27:38.744+0000] {local_task_job_runner.py:234} INFO - Task exited with return code 1
[2025-05-18T14:27:38.768+0000] {taskinstance.py:3280} INFO - 0 downstream tasks scheduled from follow-on schedule check
