[2025-05-18T14:47:44.497+0000] {taskinstance.py:1956} INFO - Dependencies all met for dep_context=non-requeueable deps ti=<TaskInstance: nyc_taxi_pipeline.load_data manual__2025-05-18T14:46:41.035828+00:00 [queued]>
[2025-05-18T14:47:44.527+0000] {taskinstance.py:1956} INFO - Dependencies all met for dep_context=requeueable deps ti=<TaskInstance: nyc_taxi_pipeline.load_data manual__2025-05-18T14:46:41.035828+00:00 [queued]>
[2025-05-18T14:47:44.529+0000] {taskinstance.py:2170} INFO - Starting attempt 1 of 2
[2025-05-18T14:47:44.577+0000] {taskinstance.py:2191} INFO - Executing <Task(PythonOperator): load_data> on 2025-05-18 14:46:41.035828+00:00
[2025-05-18T14:47:44.585+0000] {standard_task_runner.py:60} INFO - Started process 215 to run task
[2025-05-18T14:47:44.592+0000] {standard_task_runner.py:87} INFO - Running: ['***', 'tasks', 'run', 'nyc_taxi_pipeline', 'load_data', 'manual__2025-05-18T14:46:41.035828+00:00', '--job-id', '15', '--raw', '--subdir', 'DAGS_FOLDER/nyc_taxi_pipeline.py', '--cfg-path', '/tmp/tmpsmd4h2wq']
[2025-05-18T14:47:44.598+0000] {standard_task_runner.py:88} INFO - Job 15: Subtask load_data
[2025-05-18T14:47:44.628+0000] {logging_mixin.py:188} WARNING - /home/***/.local/lib/python3.8/site-packages/***/settings.py:194 DeprecationWarning: The sql_alchemy_conn option in [core] has been moved to the sql_alchemy_conn option in [database] - the old setting has been used, but please update your config.
[2025-05-18T14:47:44.689+0000] {task_command.py:423} INFO - Running <TaskInstance: nyc_taxi_pipeline.load_data manual__2025-05-18T14:46:41.035828+00:00 [running]> on host 01093a8aec31
[2025-05-18T14:47:45.061+0000] {taskinstance.py:2480} INFO - Exporting env vars: AIRFLOW_CTX_DAG_OWNER='***' AIRFLOW_CTX_DAG_ID='nyc_taxi_pipeline' AIRFLOW_CTX_TASK_ID='load_data' AIRFLOW_CTX_EXECUTION_DATE='2025-05-18T14:46:41.035828+00:00' AIRFLOW_CTX_TRY_NUMBER='1' AIRFLOW_CTX_DAG_RUN_ID='manual__2025-05-18T14:46:41.035828+00:00'
[2025-05-18T14:47:45.062+0000] {nyc_taxi_pipeline.py:50} INFO - Starting data loading...
[2025-05-18T14:47:45.066+0000] {taskinstance.py:2698} ERROR - Task failed with exception
Traceback (most recent call last):
  File "/home/airflow/.local/lib/python3.8/site-packages/airflow/models/taskinstance.py", line 433, in _execute_task
    result = execute_callable(context=context, **execute_callable_kwargs)
  File "/home/airflow/.local/lib/python3.8/site-packages/airflow/operators/python.py", line 199, in execute
    return_value = self.execute_callable()
  File "/home/airflow/.local/lib/python3.8/site-packages/airflow/operators/python.py", line 216, in execute_callable
    return self.python_callable(*self.op_args, **self.op_kwargs)
  File "/opt/airflow/dags/nyc_taxi_pipeline.py", line 58, in load_callable
    df = pd.read_parquet(cleaned_path)
  File "/home/airflow/.local/lib/python3.8/site-packages/pandas/io/parquet.py", line 509, in read_parquet
    return impl.read(
  File "/home/airflow/.local/lib/python3.8/site-packages/pandas/io/parquet.py", line 220, in read
    path_or_handle, handles, kwargs["filesystem"] = _get_path_or_handle(
  File "/home/airflow/.local/lib/python3.8/site-packages/pandas/io/parquet.py", line 110, in _get_path_or_handle
    handles = get_handle(
  File "/home/airflow/.local/lib/python3.8/site-packages/pandas/io/common.py", line 868, in get_handle
    handle = open(handle, ioargs.mode)
FileNotFoundError: [Errno 2] No such file or directory: 'C:\\Users\\jorda\\OneDrive\\Documents\\nyc-taxi-pipeline-1\\airflow-docker\\scripts\\Data\\Processed\\cleaned_data.parquet'
[2025-05-18T14:47:45.082+0000] {taskinstance.py:1138} INFO - Marking task as UP_FOR_RETRY. dag_id=nyc_taxi_pipeline, task_id=load_data, execution_date=20250518T144641, start_date=20250518T144744, end_date=20250518T144745
[2025-05-18T14:47:45.101+0000] {standard_task_runner.py:107} ERROR - Failed to execute job 15 for task load_data ([Errno 2] No such file or directory: 'C:\\Users\\jorda\\OneDrive\\Documents\\nyc-taxi-pipeline-1\\airflow-docker\\scripts\\Data\\Processed\\cleaned_data.parquet'; 215)
[2025-05-18T14:47:45.128+0000] {local_task_job_runner.py:234} INFO - Task exited with return code 1
[2025-05-18T14:47:45.151+0000] {taskinstance.py:3280} INFO - 0 downstream tasks scheduled from follow-on schedule check
