[2025-05-18T15:11:01.713+0000] {taskinstance.py:1956} INFO - Dependencies all met for dep_context=non-requeueable deps ti=<TaskInstance: nyc_taxi_pipeline.load_data manual__2025-05-18T15:05:05.522562+00:00 [queued]>
[2025-05-18T15:11:01.728+0000] {taskinstance.py:1956} INFO - Dependencies all met for dep_context=requeueable deps ti=<TaskInstance: nyc_taxi_pipeline.load_data manual__2025-05-18T15:05:05.522562+00:00 [queued]>
[2025-05-18T15:11:01.728+0000] {taskinstance.py:2170} INFO - Starting attempt 2 of 2
[2025-05-18T15:11:01.750+0000] {taskinstance.py:2191} INFO - Executing <Task(PythonOperator): load_data> on 2025-05-18 15:05:05.522562+00:00
[2025-05-18T15:11:01.756+0000] {standard_task_runner.py:60} INFO - Started process 234 to run task
[2025-05-18T15:11:01.760+0000] {standard_task_runner.py:87} INFO - Running: ['***', 'tasks', 'run', 'nyc_taxi_pipeline', 'load_data', 'manual__2025-05-18T15:05:05.522562+00:00', '--job-id', '25', '--raw', '--subdir', 'DAGS_FOLDER/nyc_taxi_pipeline.py', '--cfg-path', '/tmp/tmp315fgxf6']
[2025-05-18T15:11:01.763+0000] {standard_task_runner.py:88} INFO - Job 25: Subtask load_data
[2025-05-18T15:11:01.787+0000] {logging_mixin.py:188} WARNING - /home/***/.local/lib/python3.8/site-packages/***/settings.py:194 DeprecationWarning: The sql_alchemy_conn option in [core] has been moved to the sql_alchemy_conn option in [database] - the old setting has been used, but please update your config.
[2025-05-18T15:11:01.841+0000] {task_command.py:423} INFO - Running <TaskInstance: nyc_taxi_pipeline.load_data manual__2025-05-18T15:05:05.522562+00:00 [running]> on host 9d0e91d54ee2
[2025-05-18T15:11:02.140+0000] {taskinstance.py:2480} INFO - Exporting env vars: AIRFLOW_CTX_DAG_OWNER='***' AIRFLOW_CTX_DAG_ID='nyc_taxi_pipeline' AIRFLOW_CTX_TASK_ID='load_data' AIRFLOW_CTX_EXECUTION_DATE='2025-05-18T15:05:05.522562+00:00' AIRFLOW_CTX_TRY_NUMBER='2' AIRFLOW_CTX_DAG_RUN_ID='manual__2025-05-18T15:05:05.522562+00:00'
[2025-05-18T15:11:02.141+0000] {nyc_taxi_pipeline.py:50} INFO - Starting data loading...
[2025-05-18T15:11:03.102+0000] {taskinstance.py:2698} ERROR - Task failed with exception
Traceback (most recent call last):
  File "/home/airflow/.local/lib/python3.8/site-packages/airflow/models/taskinstance.py", line 433, in _execute_task
    result = execute_callable(context=context, **execute_callable_kwargs)
  File "/home/airflow/.local/lib/python3.8/site-packages/airflow/operators/python.py", line 199, in execute
    return_value = self.execute_callable()
  File "/home/airflow/.local/lib/python3.8/site-packages/airflow/operators/python.py", line 216, in execute_callable
    return self.python_callable(*self.op_args, **self.op_kwargs)
  File "/opt/airflow/dags/nyc_taxi_pipeline.py", line 60, in load_callable
    creds = load.read_db_credentials(yaml_path)
  File "/opt/airflow/scripts/load.py", line 27, in read_db_credentials
    raise ValueError(f'Missing keys in YAML: {missing_keys}')
ValueError: Missing keys in YAML: ['host', 'port', 'database', 'user', 'password']
[2025-05-18T15:11:03.123+0000] {taskinstance.py:1138} INFO - Marking task as FAILED. dag_id=nyc_taxi_pipeline, task_id=load_data, execution_date=20250518T150505, start_date=20250518T151101, end_date=20250518T151103
[2025-05-18T15:11:03.142+0000] {standard_task_runner.py:107} ERROR - Failed to execute job 25 for task load_data (Missing keys in YAML: ['host', 'port', 'database', 'user', 'password']; 234)
[2025-05-18T15:11:03.179+0000] {local_task_job_runner.py:234} INFO - Task exited with return code 1
[2025-05-18T15:11:03.206+0000] {taskinstance.py:3280} INFO - 0 downstream tasks scheduled from follow-on schedule check
