[2025-05-18T15:33:25.701+0000] {taskinstance.py:1956} INFO - Dependencies all met for dep_context=non-requeueable deps ti=<TaskInstance: nyc_taxi_pipeline.load_data manual__2025-05-18T15:27:27.730189+00:00 [queued]>
[2025-05-18T15:33:25.712+0000] {taskinstance.py:1956} INFO - Dependencies all met for dep_context=requeueable deps ti=<TaskInstance: nyc_taxi_pipeline.load_data manual__2025-05-18T15:27:27.730189+00:00 [queued]>
[2025-05-18T15:33:25.713+0000] {taskinstance.py:2170} INFO - Starting attempt 2 of 2
[2025-05-18T15:33:25.730+0000] {taskinstance.py:2191} INFO - Executing <Task(PythonOperator): load_data> on 2025-05-18 15:27:27.730189+00:00
[2025-05-18T15:33:25.737+0000] {standard_task_runner.py:60} INFO - Started process 282 to run task
[2025-05-18T15:33:25.739+0000] {standard_task_runner.py:87} INFO - Running: ['***', 'tasks', 'run', 'nyc_taxi_pipeline', 'load_data', 'manual__2025-05-18T15:27:27.730189+00:00', '--job-id', '31', '--raw', '--subdir', 'DAGS_FOLDER/nyc_taxi_pipeline.py', '--cfg-path', '/tmp/tmp3mlss3yk']
[2025-05-18T15:33:25.742+0000] {standard_task_runner.py:88} INFO - Job 31: Subtask load_data
[2025-05-18T15:33:25.761+0000] {logging_mixin.py:188} WARNING - /home/***/.local/lib/python3.8/site-packages/***/settings.py:194 DeprecationWarning: The sql_alchemy_conn option in [core] has been moved to the sql_alchemy_conn option in [database] - the old setting has been used, but please update your config.
[2025-05-18T15:33:25.802+0000] {task_command.py:423} INFO - Running <TaskInstance: nyc_taxi_pipeline.load_data manual__2025-05-18T15:27:27.730189+00:00 [running]> on host dddc1a061460
[2025-05-18T15:33:26.109+0000] {taskinstance.py:2480} INFO - Exporting env vars: AIRFLOW_CTX_DAG_OWNER='***' AIRFLOW_CTX_DAG_ID='nyc_taxi_pipeline' AIRFLOW_CTX_TASK_ID='load_data' AIRFLOW_CTX_EXECUTION_DATE='2025-05-18T15:27:27.730189+00:00' AIRFLOW_CTX_TRY_NUMBER='2' AIRFLOW_CTX_DAG_RUN_ID='manual__2025-05-18T15:27:27.730189+00:00'
[2025-05-18T15:33:26.111+0000] {nyc_taxi_pipeline.py:50} INFO - Starting data loading...
[2025-05-18T15:33:26.785+0000] {taskinstance.py:2698} ERROR - Task failed with exception
Traceback (most recent call last):
  File "/home/airflow/.local/lib/python3.8/site-packages/airflow/models/taskinstance.py", line 433, in _execute_task
    result = execute_callable(context=context, **execute_callable_kwargs)
  File "/home/airflow/.local/lib/python3.8/site-packages/airflow/operators/python.py", line 199, in execute
    return_value = self.execute_callable()
  File "/home/airflow/.local/lib/python3.8/site-packages/airflow/operators/python.py", line 216, in execute_callable
    return self.python_callable(*self.op_args, **self.op_kwargs)
  File "/opt/airflow/dags/nyc_taxi_pipeline.py", line 60, in load_callable
    creds = load.read_db_credentials(yaml_path)
  File "/opt/airflow/scripts/load.py", line 27, in read_db_credentials
    raise ValueError(f'Missing keys in YAML: {missing_keys}')
ValueError: Missing keys in YAML: ['host', 'port', 'database', 'user', 'password']
[2025-05-18T15:33:26.798+0000] {taskinstance.py:1138} INFO - Marking task as FAILED. dag_id=nyc_taxi_pipeline, task_id=load_data, execution_date=20250518T152727, start_date=20250518T153325, end_date=20250518T153326
[2025-05-18T15:33:26.822+0000] {standard_task_runner.py:107} ERROR - Failed to execute job 31 for task load_data (Missing keys in YAML: ['host', 'port', 'database', 'user', 'password']; 282)
[2025-05-18T15:33:26.839+0000] {local_task_job_runner.py:234} INFO - Task exited with return code 1
[2025-05-18T15:33:26.856+0000] {taskinstance.py:3280} INFO - 0 downstream tasks scheduled from follow-on schedule check
