[2025-05-18T15:28:22.883+0000] {taskinstance.py:1956} INFO - Dependencies all met for dep_context=non-requeueable deps ti=<TaskInstance: nyc_taxi_pipeline.load_data manual__2025-05-18T15:27:27.730189+00:00 [queued]>
[2025-05-18T15:28:22.902+0000] {taskinstance.py:1956} INFO - Dependencies all met for dep_context=requeueable deps ti=<TaskInstance: nyc_taxi_pipeline.load_data manual__2025-05-18T15:27:27.730189+00:00 [queued]>
[2025-05-18T15:28:22.903+0000] {taskinstance.py:2170} INFO - Starting attempt 1 of 2
[2025-05-18T15:28:22.935+0000] {taskinstance.py:2191} INFO - Executing <Task(PythonOperator): load_data> on 2025-05-18 15:27:27.730189+00:00
[2025-05-18T15:28:22.941+0000] {standard_task_runner.py:60} INFO - Started process 209 to run task
[2025-05-18T15:28:22.948+0000] {standard_task_runner.py:87} INFO - Running: ['***', 'tasks', 'run', 'nyc_taxi_pipeline', 'load_data', 'manual__2025-05-18T15:27:27.730189+00:00', '--job-id', '30', '--raw', '--subdir', 'DAGS_FOLDER/nyc_taxi_pipeline.py', '--cfg-path', '/tmp/tmpngnzk_dr']
[2025-05-18T15:28:22.952+0000] {standard_task_runner.py:88} INFO - Job 30: Subtask load_data
[2025-05-18T15:28:22.977+0000] {logging_mixin.py:188} WARNING - /home/***/.local/lib/python3.8/site-packages/***/settings.py:194 DeprecationWarning: The sql_alchemy_conn option in [core] has been moved to the sql_alchemy_conn option in [database] - the old setting has been used, but please update your config.
[2025-05-18T15:28:23.042+0000] {task_command.py:423} INFO - Running <TaskInstance: nyc_taxi_pipeline.load_data manual__2025-05-18T15:27:27.730189+00:00 [running]> on host dddc1a061460
[2025-05-18T15:28:23.436+0000] {taskinstance.py:2480} INFO - Exporting env vars: AIRFLOW_CTX_DAG_OWNER='***' AIRFLOW_CTX_DAG_ID='nyc_taxi_pipeline' AIRFLOW_CTX_TASK_ID='load_data' AIRFLOW_CTX_EXECUTION_DATE='2025-05-18T15:27:27.730189+00:00' AIRFLOW_CTX_TRY_NUMBER='1' AIRFLOW_CTX_DAG_RUN_ID='manual__2025-05-18T15:27:27.730189+00:00'
[2025-05-18T15:28:23.438+0000] {nyc_taxi_pipeline.py:50} INFO - Starting data loading...
[2025-05-18T15:28:24.578+0000] {taskinstance.py:2698} ERROR - Task failed with exception
Traceback (most recent call last):
  File "/home/airflow/.local/lib/python3.8/site-packages/airflow/models/taskinstance.py", line 433, in _execute_task
    result = execute_callable(context=context, **execute_callable_kwargs)
  File "/home/airflow/.local/lib/python3.8/site-packages/airflow/operators/python.py", line 199, in execute
    return_value = self.execute_callable()
  File "/home/airflow/.local/lib/python3.8/site-packages/airflow/operators/python.py", line 216, in execute_callable
    return self.python_callable(*self.op_args, **self.op_kwargs)
  File "/opt/airflow/dags/nyc_taxi_pipeline.py", line 60, in load_callable
    creds = load.read_db_credentials(yaml_path)
  File "/opt/airflow/scripts/load.py", line 27, in read_db_credentials
    raise ValueError(f'Missing keys in YAML: {missing_keys}')
ValueError: Missing keys in YAML: ['host', 'port', 'database', 'user', 'password']
[2025-05-18T15:28:24.601+0000] {taskinstance.py:1138} INFO - Marking task as UP_FOR_RETRY. dag_id=nyc_taxi_pipeline, task_id=load_data, execution_date=20250518T152727, start_date=20250518T152822, end_date=20250518T152824
[2025-05-18T15:28:24.627+0000] {standard_task_runner.py:107} ERROR - Failed to execute job 30 for task load_data (Missing keys in YAML: ['host', 'port', 'database', 'user', 'password']; 209)
[2025-05-18T15:28:24.690+0000] {local_task_job_runner.py:234} INFO - Task exited with return code 1
[2025-05-18T15:28:24.718+0000] {taskinstance.py:3280} INFO - 0 downstream tasks scheduled from follow-on schedule check
