[2025-05-19T09:52:19.407+0000] {taskinstance.py:1956} INFO - Dependencies all met for dep_context=non-requeueable deps ti=<TaskInstance: nyc_taxi_pipeline.load_data manual__2025-05-19T09:51:18.048420+00:00 [queued]>
[2025-05-19T09:52:19.422+0000] {taskinstance.py:1956} INFO - Dependencies all met for dep_context=requeueable deps ti=<TaskInstance: nyc_taxi_pipeline.load_data manual__2025-05-19T09:51:18.048420+00:00 [queued]>
[2025-05-19T09:52:19.423+0000] {taskinstance.py:2170} INFO - Starting attempt 1 of 2
[2025-05-19T09:52:19.446+0000] {taskinstance.py:2191} INFO - Executing <Task(PythonOperator): load_data> on 2025-05-19 09:51:18.048420+00:00
[2025-05-19T09:52:19.452+0000] {standard_task_runner.py:60} INFO - Started process 209 to run task
[2025-05-19T09:52:19.457+0000] {standard_task_runner.py:87} INFO - Running: ['***', 'tasks', 'run', 'nyc_taxi_pipeline', 'load_data', 'manual__2025-05-19T09:51:18.048420+00:00', '--job-id', '52', '--raw', '--subdir', 'DAGS_FOLDER/nyc_taxi_pipeline.py', '--cfg-path', '/tmp/tmpgbqnlqoe']
[2025-05-19T09:52:19.462+0000] {standard_task_runner.py:88} INFO - Job 52: Subtask load_data
[2025-05-19T09:52:19.492+0000] {logging_mixin.py:188} WARNING - /home/***/.local/lib/python3.8/site-packages/***/settings.py:194 DeprecationWarning: The sql_alchemy_conn option in [core] has been moved to the sql_alchemy_conn option in [database] - the old setting has been used, but please update your config.
[2025-05-19T09:52:19.552+0000] {task_command.py:423} INFO - Running <TaskInstance: nyc_taxi_pipeline.load_data manual__2025-05-19T09:51:18.048420+00:00 [running]> on host 8411883fc7e4
[2025-05-19T09:52:19.904+0000] {taskinstance.py:2480} INFO - Exporting env vars: AIRFLOW_CTX_DAG_OWNER='***' AIRFLOW_CTX_DAG_ID='nyc_taxi_pipeline' AIRFLOW_CTX_TASK_ID='load_data' AIRFLOW_CTX_EXECUTION_DATE='2025-05-19T09:51:18.048420+00:00' AIRFLOW_CTX_TRY_NUMBER='1' AIRFLOW_CTX_DAG_RUN_ID='manual__2025-05-19T09:51:18.048420+00:00'
[2025-05-19T09:52:19.906+0000] {nyc_taxi_pipeline.py:50} INFO - Starting data loading...
[2025-05-19T09:52:19.920+0000] {load.py:67} ERROR - Failed during chunked parquet upload: read_table() got an unexpected keyword argument 'chunksize'
Traceback (most recent call last):
  File "/opt/airflow/scripts/load.py", line 56, in upload_parquet_in_chunks
    df_iter = pd.read_parquet(parquet_file, chunksize=chunksize)
  File "/home/airflow/.local/lib/python3.8/site-packages/pandas/io/parquet.py", line 509, in read_parquet
    return impl.read(
  File "/home/airflow/.local/lib/python3.8/site-packages/pandas/io/parquet.py", line 227, in read
    pa_table = self.api.parquet.read_table(
TypeError: read_table() got an unexpected keyword argument 'chunksize'
[2025-05-19T09:52:19.927+0000] {nyc_taxi_pipeline.py:69} INFO - Data successfully loaded
[2025-05-19T09:52:19.928+0000] {python.py:201} INFO - Done. Returned value was: None
[2025-05-19T09:52:19.942+0000] {taskinstance.py:1138} INFO - Marking task as SUCCESS. dag_id=nyc_taxi_pipeline, task_id=load_data, execution_date=20250519T095118, start_date=20250519T095219, end_date=20250519T095219
[2025-05-19T09:52:19.995+0000] {local_task_job_runner.py:234} INFO - Task exited with return code 0
[2025-05-19T09:52:20.020+0000] {taskinstance.py:3280} INFO - 0 downstream tasks scheduled from follow-on schedule check
